2024-12-19 07:30:41,159 - INFO - 开始数据处理...
2024-12-19 07:30:41,159 - INFO - 输入文件: /home/lx/XGBOOST-LSTM-COAL/data/raw/queue_data_offset_sorted_utf8.csv
2024-12-19 07:30:41,159 - INFO - 输出目录: /home/lx/XGBOOST-LSTM-COAL/data/processed/lstm
2024-12-19 07:30:41,369 - ERROR - 处理过程中出现错误: 'daily_queue_count'
Traceback (most recent call last):
  File "/root/anaconda3/envs/tf2/lib/python3.9/site-packages/pandas/core/indexes/base.py", line 3621, in get_loc
    return self._engine.get_loc(casted_key)
  File "pandas/_libs/index.pyx", line 136, in pandas._libs.index.IndexEngine.get_loc
  File "pandas/_libs/index.pyx", line 163, in pandas._libs.index.IndexEngine.get_loc
  File "pandas/_libs/hashtable_class_helper.pxi", line 5198, in pandas._libs.hashtable.PyObjectHashTable.get_item
  File "pandas/_libs/hashtable_class_helper.pxi", line 5206, in pandas._libs.hashtable.PyObjectHashTable.get_item
KeyError: 'daily_queue_count'

The above exception was the direct cause of the following exception:

Traceback (most recent call last):
  File "/home/lx/XGBOOST-LSTM-COAL/scripts/lstm_process_data.py", line 61, in main
    X, y = preprocessor.process_data(data_path, save_path)
  File "/home/lx/XGBOOST-LSTM-COAL/src/data/lstm_data_processor.py", line 47, in process_data
    df = self.apply_feature_engineering(df)
  File "/home/lx/XGBOOST-LSTM-COAL/src/data/lstm_data_processor.py", line 68, in apply_feature_engineering
    df = self.feature_engineer.create_interaction_features(df)
  File "/home/lx/XGBOOST-LSTM-COAL/src/data/lstm_feature_engineer.py", line 128, in create_interaction_features
    df[f'{col1}_{col2}_prod'] = df[col1] * df[col2]
  File "/root/anaconda3/envs/tf2/lib/python3.9/site-packages/pandas/core/frame.py", line 3505, in __getitem__
    indexer = self.columns.get_loc(key)
  File "/root/anaconda3/envs/tf2/lib/python3.9/site-packages/pandas/core/indexes/base.py", line 3623, in get_loc
    raise KeyError(key) from err
KeyError: 'daily_queue_count'
